#VRML_SIM R2023b utf8

EXTERNPROTO "https://raw.githubusercontent.com/cyberbotics/webots/R2023b/projects/objects/backgrounds/protos/TexturedBackground.proto"
EXTERNPROTO "https://raw.githubusercontent.com/cyberbotics/webots/R2023b/projects/objects/backgrounds/protos/TexturedBackgroundLight.proto"
EXTERNPROTO "https://raw.githubusercontent.com/cyberbotics/webots/R2023b/projects/objects/floors/protos/RectangleArena.proto"
EXTERNPROTO "https://raw.githubusercontent.com/cyberbotics/webots/R2023b/projects/appearances/protos/OsbWood.proto"

WorldInfo {
}
Viewpoint {
  orientation 0.1438616695888862 0.11887003516149967 -0.9824325599061758 1.777826296620528
  position 0.3763787155332399 0.619717471743981 0.4590523070067848
}
DEF box Solid {
  translation 0.138564 0 0.16
  rotation 0 1 0 2.618
  children [
    DEF box0 Shape {
      appearance OsbWood {
        textureTransform TextureTransform {
        }
      }
      geometry Box {
        size 1 0.2 0.02
      }
    }
  ]
}
TexturedBackground {
}
TexturedBackgroundLight {
}
RectangleArena {
  translation 0 0 -0.02
}
Robot {
  translation 0 0 0.16
  children [
    DEF smile Pose {
      translation 0.314822 0 0.14206
      rotation 0.44721501644074235 -0.44721501644074235 0.7745950284760504 -1.823475307179586
      children [
        Shape {
          appearance PBRAppearance {
            baseColor 1 0.278431 1
            roughness 1
            metalness 0
          }
          geometry Cylinder {
            height 0.018
            radius 0.009
            subdivision 3
          }
        }
      ]
    }
    DistanceSensor {
      translation 0.42 0.02 0.063
      rotation 0 0 -1 -0.499
      children [
        DEF sensor Pose {
          translation -0.107874 0.0638768 0.105965
          rotation 0.8172627342858622 0.5237178297252209 -0.2404189218333299 -2.1604753071795866
          children [
            Shape {
              appearance PBRAppearance {
                baseColor 1 1 0
                roughness 1
                metalness 0
              }
              geometry Cylinder {
                height 0.004
                radius 0.008
              }
            }
          ]
        }
      ]
      name "DS0"
      lookupTable [
        0 1024 0
        0.05 1020 0
        0.15 0 0
      ]
      numberOfRays 2
    }
    DistanceSensor {
      translation 0.42 0.02 0.063
      rotation 0 0 -1 -0.499
      children [
        DEF sensor Pose {
          translation -0.128288 0.0194497 0.11308
          rotation 0.6054281025050408 0.6284361064005263 -0.48839008268933193 -2.618705307179586
          children [
            Shape {
              appearance PBRAppearance {
                baseColor 1 1 0
                roughness 1
                metalness 0
              }
              geometry Cylinder {
                height 0.004
                radius 0.008
              }
            }
          ]
        }
      ]
      name "DS1"
      lookupTable [
        0 1024 0
        0.05 1020 0
        0.15 0 0
      ]
      numberOfRays 2
    }
    DEF right_wheel_motor HingeJoint {
      jointParameters HingeJointParameters {
      }
      device [
        PositionSensor {
          name "rightWheelSensor"
        }
        RotationalMotor {
          name "right wheel motor"
          consumptionFactor 70
        }
      ]
      endPoint Solid {
        children [
          Pose {
            translation 0.350275 -0.0512926 0.158983
            rotation -0.9999967723417943 0.002540729421580232 2.397439454201474e-09 1.56826
            children [
              Shape {
                appearance PBRAppearance {
                  baseColor 1 0 0
                  roughness 1
                  metalness 0
                }
                geometry Cylinder {
                  height 0.01
                  radius 0.025
                }
              }
            ]
          }
        ]
        name "rightWheel"
      }
    }
    DEF left_wheel_motor HingeJoint {
      jointParameters HingeJointParameters {
        position 2.758765836532025e-07
      }
      device [
        PositionSensor {
          name "leftWheelSensor"
        }
        RotationalMotor {
          name "left wheel motor"
          consumptionFactor 70
        }
      ]
      endPoint Solid {
        translation 0.35088400000000003 0.04503155539903102 0.1616700124231579
        rotation -0.2661169774669573 -0.26524423278463855 0.9267293301057972 1.6468152337641269
        children [
          DEF wheel Pose {
            rotation 0.5773502691896257 0.5773502691896257 -0.5773502691896257 -2.094
            children [
              Shape {
                appearance PBRAppearance {
                  baseColor 1 0 0
                  roughness 1
                  metalness 0
                }
                geometry Cylinder {
                  height 0.01
                  radius 0.025
                }
              }
            ]
          }
        ]
        name "leftWheel"
        physics Physics {
          density -1
          mass 0.05
        }
        linearVelocity 3.727215572583231e-13 -4.288018236005623e-07 1.1943179252682524e-07
        angularVelocity 2.652314126672319e-06 1.9164561495633224e-12 -1.411913886016488e-12
      }
    }
    Pose {
      translation 0.339085 0 0.172679
      rotation 0 1 0 -0.523595307179586
      children [
        Shape {
          appearance PBRAppearance {
            baseColor 0 0 1
            roughness 1
            metalness 0
          }
          geometry DEF cylinder Cylinder {
            height 0.08
            radius 0.045
          }
        }
      ]
    }
    Altimeter {
    }
  ]
}
